Workbook

Sheet Cleaned_Data
A1: job_title | B1: company | C1: city | D1: sector | E1: employment_type | F1: experience_required | G1: salary_pkr_month | H1: platform | I1: date_posted_or_seen | J1: source_url | K1: notes | L1: city_clean | M1: work_mode | N1: contract_type | O1: experience_level | P1: salary_disclosed | Q1: date_parsed | R1: salary_currency | S1: salary_value_monthly | T1: salary_note | U1: search_text
A2: Data Analyst | B2: Millat Tractors | C2: Rawalpindi | D2: Manufacturing | E2: Hybrid | F2: Senior (5-8 yrs) | G2: Not disclosed | H2: Rozee.pk | I2: 2026-06 | J2: https://www.rozee.pk/search/data-analyst-jobs-in-pakistan | K2: From Rozee.pk live search results | L2: Rawalpindi | M2: Hybrid | N2: Not disclosed | O2: Senior | P2: No | Q2: 2026-06-01 | U2: data analyst | from rozee.pk live search results | manufacturing
A3: Upwork Bidder / Business Analyst | B3: Dotgenic Systems | C3: Lahore | D3: IT Services | E3: Not disclosed | F3: Fresh | G3: Not disclosed | H3: Rozee.pk | I3: 2026-06-10 | J3: https://www.rozee.pk/search/data-analyst-jobs-in-pakistan | K3: Client acquisition + data analysis role | L3: Lahore | M3: Not disclosed | N3: Not disclosed | O3: Entry/Fresh | P3: No | Q3: 2026-06-10 | U3: upwork bidder / business analyst | client acquisition + data analysis role | it services
A4: Associate Financial Analyst | B4: ASTO Life Sciences | C4: Lahore | D4: Pharma/Life Sciences | E4: Not disclosed | F4: 3 years | G4: 120000-120000 | H4: Rozee.pk | I4: 2026-06-15 | J4: https://www.rozee.pk/search/data-analyst-jobs-in-pakistan | K4: Only listing with exact disclosed salary | L4: Lahore | M4: Not disclosed | N4: Not disclosed | O4: Mid | P4: Yes | Q4: 2026-06-15 | R4: PKR | S4: 120000 | U4: associate financial analyst | only listing with exact disclosed salary | pharma/life sciences
A5: Financial Analyst | B5: KSB Pumps Company Limited | C5: Lahore | D5: Manufacturing | E5: Not disclosed | F5: Experienced | G5: Not disclosed | H5: Rozee.pk | I5: 2026-06 | J5: https://www.rozee.pk/search/data-analyst-jobs-in-pakistan | L5: Lahore | M5: Not disclosed | N5: Not disclosed | O5: Mid | P5: No | Q5: 2026-06-01 | U5: financial analyst | | manufacturing
A6: Senior Project Analyst | B6: Now IT Solutions | C6: Not disclosed | D6: IT Services | E6: Not disclosed | F6: Experienced | G6: Not disclosed | H6: Rozee.pk | I6: 2026-06 | J6: https://www.rozee.pk/search/data-analyst-jobs-in-pakistan | K6: Techno-functional PMO role | L6: Not disclosed | M6: Not disclosed | N6: Not disclosed | O6: Mid | P6: No | Q6: 2026-06-01 | U6: senior project analyst | techno-functional pmo role | it services
A7: Senior Analyst | B7: Bank Al Habib Limited | C7: Not disclosed | D7: Banking | E7: Not disclosed | F7: 3+ years | G7: Not disclosed | H7: Rozee.pk | I7: 2026-06 | J7: https://www.rozee.pk/search/data-analyst-jobs-in-pakistan | K7: Power BI / Power Query skills required | L7: Not disclosed | M7: Not disclosed | N7: Not disclosed | O7: Mid | P7: No | Q7: 2026-06-01 | U7: senior analyst | power bi / power query skills required | banking
A8: Data and Reporting Analyst | B8: Confidential (NGO/Program) | C8: Not disclosed | D8: NGO & Development | E8: Not disclosed | F8: Not disclosed | G8: Not disclosed | H8: Rozee.pk | I8: 2026-06 | J8: https://www.rozee.pk/search/data-analyst-jobs-in-pakistan | K8: Program data accuracy and integrity role | L8: Not disclosed | M8: Not disclosed | N8: Not disclosed | O8: Not disclosed | P8: No | Q8: 2026-06-01 | U8: data and reporting analyst | program data accuracy and integrity role | ngo & development
A9: MIS Analyst | B9: Confidential (Health Program) | C9: Not disclosed | D9: NGO & Development | E9: Not disclosed | F9: Not disclosed | G9: Not disclosed | H9: Rozee.pk | I9: 2026-06 | J9: https://www.rozee.pk/search/data-analyst-jobs-in-pakistan | K9: Health Management Information Systems | L9: Not disclosed | M9: Not disclosed | N9: Not disclosed | O9: Not disclosed | P9: No | Q9: 2026-06-01 | U9: mis analyst | health management information systems | ngo & development
A10: Junior SAP Analytics Cloud Analyst | B10: Confidential Multinational | C10: Not disclosed | D10: FMCG/Multinational | E10: Entry Level | F10: Entry level | G10: Not disclosed | H10: Rozee.pk | I10: 2026-06 | J10: https://www.rozee.pk/search/data-analyst-jobs-in-pakistan | K10: SAP Analytics Cloud dashboarding | L10: Not disclosed | M10: Not disclosed | N10: Not disclosed | O10: Entry/Fresh | P10: No | Q10: 2026-06-01 | U10: junior sap analytics cloud analyst | sap analytics cloud dashboarding | fmcg/multinational
A11: Data Analyst Associate | B11: Gazala Group | C11: Karachi (North Nazimabad) | D11: Healthcare Consultancy | E11: Not disclosed | F11: Not disclosed | G11: Not disclosed | H11: Rozee.pk | I11: 2026-06 | J11: https://www.rozee.pk/search/data-analyst-jobs-in-pakistan | K11: Excel PivotTables, R, data visualization | L11: Karachi | M11: Not disclosed | N11: Not disclosed | O11: Not disclosed | P11: No | Q11: 2026-06-01 | U11: data analyst associate | excel pivottables, r, data visualization | healthcare consultancy
A12: Data Research and Data Analyst | B12: S&N Consulting Group Pvt Ltd | C12: Multan (Shah Rukn-e-Alam) | D12: Consulting | E12: Not disclosed | F12: Not disclosed | G12: Not disclosed | H12: Rozee.pk | I12: 2026-06 | J12: https://www.rozee.pk/search/data-analyst-jobs-in-pakistan | K12: Data mining and database management | L12: Multan | M12: Not disclosed | N12: Not disclosed | O12: Not disclosed | P12: No | Q12: 2026-06-01 | U12: data research and data analyst | data mining and database management | consulting
A13: Data Analyst | B13: Rozee (internal posting) | C13: Karachi | D13: Agri-Tech | E13: Not disclosed | F13: Not disclosed | G13: Not disclosed | H13: Rozee.pk | I13: 2026-06 | J13: https://www.rozee.pk/EN/rozee-data-analyst-jobs-1555112 | K13: Crop price prediction using Python and Power BI | L13: Karachi | M13: Not disclosed | N13: Not disclosed | O13: Not disclosed | P13: No | Q13: 2026-06-01 | U13: data analyst | crop price prediction using python and power bi | agri-tech
A14: Data Analyst/Reporting - Microsoft Power BI | B14: GRID Systems | C14: Islamabad | D14: IT Services | E14: Not disclosed | F14: Not disclosed | G14: Not disclosed | H14: Glassdoor | I14: 2026-06 | J14: https://www.glassdoor.com/Job/pakistan-data-analyst-jobs-SRCH_IL.0,8_IN192_KO9,21.htm | K14: Company rating 4.6/5 on Glassdoor | L14: Islamabad | M14: Not disclosed | N14: Not disclosed | O14: Not disclosed | P14: No | Q14: 2026-06-01 | U14: data analyst/reporting - microsoft power bi | company rating 4.6/5 on glassdoor | it services
A15: Data Conversion Analyst | B15: Contour Software | C15: Lahore | D15: IT Services | E15: Not disclosed | F15: Not disclosed | G15: Not disclosed | H15: Glassdoor | I15: 2026-06 | J15: https://www.glassdoor.com/Job/pakistan-data-analyst-jobs-SRCH_IL.0,8_IN192_KO9,21.htm | K15: Company rating 4.4/5 on Glassdoor | L15: Lahore | M15: Not disclosed | N15: Not disclosed | O15: Not disclosed | P15: No | Q15: 2026-06-01 | U15: data conversion analyst | company rating 4.4/5 on glassdoor | it services
A16: Data Analyst | B16: Metallicus | C16: Pakistan (Remote/Hybrid) | D16: Fintech/Blockchain | E16: Not disclosed | F16: Not disclosed | G16: Not disclosed | H16: Glassdoor | I16: 2026-06 | J16: https://www.glassdoor.com/Job/pakistan-data-analyst-jobs-SRCH_IL.0,8_IN192_KO9,21.htm | K16: Company rating 4.0/5 on Glassdoor | L16: Remote/Unspecified | M16: Not disclosed | N16: Not disclosed | O16: Not disclosed | P16: No | Q16: 2026-06-01 | U16: data analyst | company rating 4.0/5 on glassdoor | fintech/blockchain
A17: Data Analyst | B17: Dignosco | C17: Lahore | D17: EdTech/Consulting | E17: Full-time | F17: Not disclosed | G17: 30000-35000 | H17: Glassdoor | I17: 2026-06 | J17: https://www.glassdoor.com/Job/lahore-data-analyst-jobs-SRCH_IL.0,6_IC3206630_KO7,19.htm | K17: Job Code 0019/14; Department Counselling; exact disclosed salary range | L17: Lahore | M17: Not disclosed | N17: Full-time | O17: Not disclosed | P17: Yes | Q17: 2026-06-01 | R17: PKR | S17: 32500 | U17: data analyst | job code 0019/14; department counselling; exact disclosed salary range | edtech/consulting
A18: Lead/Senior Data Analyst - Python/SQL | B18: ValueMomentum | C18: Pakistan | D18: IT Services / Insurance Tech | E18: Not disclosed | F18: Not disclosed | G18: Not disclosed | H18: Glassdoor | I18: 2026-05 | J18: https://www.glassdoor.com/Job/pakistan-data-analytics-jobs-SRCH_IL.0,8_IN192_KO9,23.htm | K18: UK/US P&C Insurance domain experience required | L18: Remote/Unspecified | M18: Not disclosed | N18: Not disclosed | O18: Not disclosed | P18: No | Q18: 2026-05-01 | U18: lead/senior data analyst - python/sql | uk/us p&c insurance domain experience required | it services / insurance tech
A19: Data Analyst | B19: Creative Chaos | C19: Not disclosed | D19: IT Services | E19: Not disclosed | F19: Not disclosed | G19: Not disclosed | H19: Bayt.com | I19: 2026-05 | J19: https://www.bayt.com/en/pakistan/jobs/data-analyst-jobs/ | L19: Not disclosed | M19: Not disclosed | N19: Not disclosed | O19: Not disclosed | P19: No | Q19: 2026-05-01 | U19: data analyst | | it services
A20: Sr. Data Scientist | B20: Confidential | C20: Karachi/Lahore/Islamabad | D20: IT Services | E20: Onsite | F20: Senior | G20: PKR salary (not disclosed) | H20: Bayt.com | I20: 2026-05 | J20: https://www.bayt.com/en/pakistan/jobs/data-analyst-jobs/ | L20: Multi-city | M20: Onsite | N20: Not disclosed | O20: Senior | P20: No | Q20: 2026-05-01 | U20: sr. data scientist | | it services
A21: Senior Manager Data Modeler | B21: MetLife (MGCC) | C21: Karachi/Islamabad | D21: Insurance/Global Capability Center | E21: Onsite | F21: Senior/Manager | G21: Not disclosed | H21: Bayt.com | I21: 2026-05 | J21: https://www.bayt.com/en/pakistan/jobs/data-analyst-jobs/ | K21: Morning shift; global capability center role | L21: Multi-city | M21: Onsite | N21: Not disclosed | O21: Senior | P21: No | Q21: 2026-05-01 | U21: senior manager data modeler | morning shift; global capability center role | insurance/global capability center
A22: Data Engineer | B22: Confidential | C22: Karachi | D22: Technology | E22: Not disclosed | F22: Not disclosed | G22: Not disclosed | H22: LinkedIn | I22: 2026-06 | J22: https://pk.linkedin.com/jobs/data-analyst-jobs | K22: Actively hiring | L22: Karachi | M22: Not disclosed | N22: Not disclosed | O22: Not disclosed | P22: No | Q22: 2026-06-01 | U22: data engineer | actively hiring | technology
A23: Power BI Expert | B23: Confidential | C23: Rawalpindi | D23: Technology | E23: Not disclosed | F23: Not disclosed | G23: Not disclosed | H23: LinkedIn | I23: 2026-06 | J23: https://pk.linkedin.com/jobs/data-analyst-jobs | L23: Rawalpindi | M23: Not disclosed | N23: Not disclosed | O23: Not disclosed | P23: No | Q23: 2026-06-01 | U23: power bi expert | | technology
A24: Business Intelligence Specialist | B24: Confidential | C24: Lahore | D24: Technology | E24: Not disclosed | F24: Not disclosed | G24: Not disclosed | H24: LinkedIn | I24: 2026-06 | J24: https://pk.linkedin.com/jobs/data-analyst-jobs | K24: Actively hiring | L24: Lahore | M24: Not disclosed | N24: Not disclosed | O24: Not disclosed | P24: No | Q24: 2026-06-01 | U24: business intelligence specialist | actively hiring | technology
A25: Senior Data Analyst | B25: Confidential | C25: Punjab | D25: Technology | E25: Not disclosed | F25: Senior | G25: Not disclosed | H25: LinkedIn | I25: 2026-06 | J25: https://pk.linkedin.com/jobs/data-analyst-jobs | K25: Actively hiring | L25: Punjab (unspecified city) | M25: Not disclosed | N25: Not disclosed | O25: Senior | P25: No | Q25: 2026-06-01 | U25: senior data analyst | actively hiring | technology
A26: Remote Data Science Analyst | B26: Confidential | C26: Pakistan (Remote) | D26: Technology | E26: Remote | F26: Not disclosed | G26: Not disclosed | H26: LinkedIn | I26: 2026-06 | J26: https://pk.linkedin.com/jobs/data-analyst-jobs | K26: Actively hiring | L26: Remote/Unspecified | M26: Remote | N26: Not disclosed | O26: Not disclosed | P26: No | Q26: 2026-06-01 | U26: remote data science analyst | actively hiring | technology
A27: Analyst - Insights & Analytics | B27: Confidential | C27: Islamabad | D27: Technology | E27: Not disclosed | F27: Not disclosed | G27: Not disclosed | H27: LinkedIn | I27: 2026-06 | J27: https://pk.linkedin.com/jobs/data-analyst-jobs | K27: Actively hiring | L27: Islamabad | M27: Not disclosed | N27: Not disclosed | O27: Not disclosed | P27: No | Q27: 2026-06-01 | U27: analyst - insights & analytics | actively hiring | technology
A28: Data Analyst - Residual Value Monetisation | B28: Confidential | C28: Lahore | D28: Automotive/Fintech | E28: Onsite | F28: Not disclosed | G28: USD salary (not disclosed) | H28: LinkedIn | I28: 2026-06 | J28: https://pk.linkedin.com/jobs/data-analyst-jobs | K28: Rare USD-denominated onsite role | L28: Lahore | M28: Onsite | N28: Not disclosed | O28: Not disclosed | P28: No | Q28: 2026-06-01 | U28: data analyst - residual value monetisation | rare usd-denominated onsite role | automotive/fintech
A29: Python Data Analyst | B29: Confidential | C29: Islamabad | D29: Technology | E29: Not disclosed | F29: Not disclosed | G29: Not disclosed | H29: LinkedIn | I29: 2026-06 | J29: https://pk.linkedin.com/jobs/data-analyst-jobs | K29: Actively hiring | L29: Islamabad | M29: Not disclosed | N29: Not disclosed | O29: Not disclosed | P29: No | Q29: 2026-06-01 | U29: python data analyst | actively hiring | technology
A30: BI Developer | B30: Confidential | C30: Lahore | D30: Technology | E30: Not disclosed | F30: Not disclosed | G30: Not disclosed | H30: LinkedIn | I30: 2026-06 | J30: https://pk.linkedin.com/jobs/data-analyst-jobs | K30: Actively hiring | L30: Lahore | M30: Not disclosed | N30: Not disclosed | O30: Not disclosed | P30: No | Q30: 2026-06-01 | U30: bi developer | actively hiring | technology
A31: Data Analyst - Crystal Reports | B31: Confidential | C31: Karachi | D31: Technology | E31: Not disclosed | F31: Not disclosed | G31: Not disclosed | H31: LinkedIn | I31: 2026-06 | J31: https://pk.linkedin.com/jobs/data-analytics-jobs | L31: Karachi | M31: Not disclosed | N31: Not disclosed | O31: Not disclosed | P31: No | Q31: 2026-06-01 | U31: data analyst - crystal reports | | technology
A32: Assistant Manager - Business Intelligence | B32: Confidential | C32: Islamabad | D32: Technology | E32: Not disclosed | F32: Assistant Manager | G32: Not disclosed | H32: LinkedIn | I32: 2026-06 | J32: https://pk.linkedin.com/jobs/data-analytics-jobs | K32: Actively hiring | L32: Islamabad | M32: Not disclosed | N32: Not disclosed | O32: Senior | P32: No | Q32: 2026-06-01 | U32: assistant manager - business intelligence | actively hiring | technology
A33: Business Intelligence Analyst | B33: Confidential | C33: Lahore (Johar Town) | D33: Technology | E33: Not disclosed | F33: Not disclosed | G33: Not disclosed | H33: LinkedIn | I33: 2026-06 | J33: https://pk.linkedin.com/jobs/data-analytics-jobs | L33: Lahore | M33: Not disclosed | N33: Not disclosed | O33: Not disclosed | P33: No | Q33: 2026-06-01 | U33: business intelligence analyst | | technology
A34: Lead Data Analyst | B34: Confidential | C34: Lahore | D34: Technology | E34: Not disclosed | F34: Lead | G34: Not disclosed | H34: LinkedIn | I34: 2026-06 | J34: https://pk.linkedin.com/jobs/data-analytics-jobs | K34: Actively hiring | L34: Lahore | M34: Not disclosed | N34: Not disclosed | O34: Senior | P34: No | Q34: 2026-06-01 | U34: lead data analyst | actively hiring | technology
A35: Data Analyst (Onsite Lahore) | B35: Confidential | C35: Lahore | D35: Technology | E35: Onsite | F35: Not disclosed | G35: USD salary (not disclosed) | H35: LinkedIn | I35: 2026-06 | J35: https://pk.linkedin.com/jobs/data-analytics-jobs | K35: USD-denominated onsite role | L35: Lahore | M35: Onsite | N35: Not disclosed | O35: Not disclosed | P35: No | Q35: 2026-06-01 | U35: data analyst (onsite lahore) | usd-denominated onsite role | technology
A36: Data Scientist | B36: Confidential | C36: Karachi | D36: Technology | E36: Not disclosed | F36: Not disclosed | G36: Not disclosed | H36: LinkedIn | I36: 2026-06 | J36: https://pk.linkedin.com/jobs/data-analytics-jobs | K36: Actively hiring | L36: Karachi | M36: Not disclosed | N36: Not disclosed | O36: Not disclosed | P36: No | Q36: 2026-06-01 | U36: data scientist | actively hiring | technology
A37: Assistant Manager - Data Analytics | B37: Confidential | C37: Karachi | D37: Technology | E37: Not disclosed | F37: Assistant Manager | G37: Not disclosed | H37: LinkedIn | I37: 2026-06 | J37: https://pk.linkedin.com/jobs/data-analysis-jobs | K37: Actively hiring | L37: Karachi | M37: Not disclosed | N37: Not disclosed | O37: Senior | P37: No | Q37: 2026-06-01 | U37: assistant manager - data analytics | actively hiring | technology
A38: Trainee Data Science | B38: Confidential | C38: Lahore | D38: Technology | E38: Trainee | F38: Entry level | G38: Not disclosed | H38: LinkedIn | I38: 2026-06 | J38: https://pk.linkedin.com/jobs/data-analysis-jobs | L38: Lahore | M38: Not disclosed | N38: Trainee | O38: Entry/Fresh | P38: No | Q38: 2026-06-01 | U38: trainee data science | | technology
A39: Business Analyst - Agri | B39: Confidential | C39: Karachi | D39: Agriculture | E39: Not disclosed | F39: Not disclosed | G39: Not disclosed | H39: LinkedIn | I39: 2026-06 | J39: https://pk.linkedin.com/jobs/data-analysis-jobs | K39: Actively hiring | L39: Karachi | M39: Not disclosed | N39: Not disclosed | O39: Not disclosed | P39: No | Q39: 2026-06-01 | U39: business analyst - agri | actively hiring | agriculture
A40: Data Scientist | B40: Habib Bank AG Zurich | C40: Karachi | D40: Banking | E40: Not disclosed | F40: Not disclosed | G40: Not disclosed | H40: LinkedIn | I40: 2026-04-14 | J40: https://pk.linkedin.com/jobs/view/data-scientist-at-habib-bank-ag-zurich-4399532611 | K40: Individual job posting URL | L40: Karachi | M40: Not disclosed | N40: Not disclosed | O40: Not disclosed | P40: No | Q40: 2026-04-14 | U40: data scientist | individual job posting url | banking
...

Sheet Macro_Context_PBS
A1: National Labour Market Context (Official PBS Data)
A3: Indicator | B3: Value | C3: Unit | D3: Period | E3: Source
A4: Overall unemployment rate | B4: 6.9 | C4: percent | D4: 2024-25 | E4: Pakistan Bureau of Statistics - Labour Force Survey 2024-25
A5: Previous unemployment rate | B5: 6.3 | C5: percent | D5: 2020-21 | E5: Pakistan Bureau of Statistics - Labour Force Survey 2020-21
A6: Female unemployment rate | B6: 9.7 | C6: percent | D6: 2024-25 | E6: Pakistan Bureau of Statistics - Labour Force Survey 2024-25
A7: Labour Force Participation Rate (LFPR) | B7: 47.7 | C7: percent | D7: 2024-25 | E7: Pakistan Bureau of Statistics - Labour Force Survey 2024-25 (13th ICLS)
A8: Previous LFPR | B8: 44.9 | C8: percent | D8: 2020-21 | E8: Pakistan Bureau of Statistics - Labour Force Survey 2020-21
A9: Services sector share of employment | B9: 41.2 | C9: percent | D9: 2024 | E9: Government of Pakistan - Planning Commission press release
A10: Agriculture sector share of employment | B10: 33.1 | C10: percent | D10: 2024 | E10: Government of Pakistan - Planning Commission press release
A11: Previous agriculture sector share | B11: 37.4 | C11: percent | D11: 2021 | E11: Government of Pakistan - Planning Commission press release
A12: Average monthly wage | B12: 39000 | C12: PKR | D12: 2024-25 | E12: Government of Pakistan - Planning Commission press release
A13: Previous average monthly wage | B13: 24000 | C13: PKR | D13: 2013 baseline | E13: Government of Pakistan - Planning Commission press release
A14: Gender wage gap | B14: 2000 | C14: PKR per month | D14: 2024-25 | E14: Government of Pakistan - Planning Commission press release
A15: Previous gender wage gap | B15: 4500 | C15: PKR per month | D15: 2020-21 | E15: Government of Pakistan - Planning Commission press release
... A18: Households surveyed for LFS 2024-25 | B18: 54000 | C18: households | D18: 2024-25 | E18: Pakistan Bureau of Statistics - Labour Force Survey 2024-25
A20: Sample vs National Comparison
A21: Metric | B21: Our Sample (155 listings) | C21: Context / Note
A22: Salary transparency (% listings disclosing salary in any form) | B22: =COUNTIF(Cleaned_Data!P2:P156,"Yes")/COUNTA(Cleaned_Data!P2:P156) -> 0.025806452 | C22: Reflects same wage-opacity pattern as Pakistan's large informal labour sector (agriculture 33.1% + informal services)

Sheet Summary_City
A1: City-wise Job Listing Distribution
A3: City | B3: Number of Listings
A4: Karachi | B4: =COUNTIF(Cleaned_Data!L2:L156,A4) -> 43
A5: Lahore | B5: =COUNTIF(Cleaned_Data!L2:L156,A5) -> 35
A6: Remote/Unspecified | B6: =COUNTIF(Cleaned_Data!L2:L156,A6) -> 34
A7: Islamabad | B7: =COUNTIF(Cleaned_Data!L2:L156,A7) -> 16
A8: Not disclosed | B8: =COUNTIF(Cleaned_Data!L2:L156,A8) -> 9
A9: Rawalpindi | B9: =COUNTIF(Cleaned_Data!L2:L156,A9) -> 5
A10: Hyderabad | B10: =COUNTIF(Cleaned_Data!L2:L156,A10) -> 4
A11: Multi-city | B11: =COUNTIF(Cleaned_Data!L2:L156,A11) -> 3
A12: Faisalabad | B12: =COUNTIF(Cleaned_Data!L2:L156,A12) -> 3
A13: Multan | B13: =COUNTIF(Cleaned_Data!L2:L156,A13) -> 1
A14: Punjab (unspecified city) | B14: =COUNTIF(Cleaned_Data!L2:L156,A14) -> 1
A15: Sahiwal | B15: =COUNTIF(Cleaned_Data!L2:L156,A15) -> 1
A16: Total | B16: =SUM(B4:B15) -> 155

Sheet Summary_Platform
A1: Platform-wise Listing Source
A3: Platform | B3: Number of Listings
A4: Indeed Pakistan | B4: =COUNTIF(Cleaned_Data!H2:H156,A4) -> 67
A5: Glassdoor | B5: =COUNTIF(Cleaned_Data!H2:H156,A5) -> 37
A6: LinkedIn | B6: =COUNTIF(Cleaned_Data!H2:H156,A6) -> 19
A7: BeBee | B7: =COUNTIF(Cleaned_Data!H2:H156,A7) -> 17
A8: Rozee.pk | B8: =COUNTIF(Cleaned_Data!H2:H156,A8) -> 12
A9: Bayt.com | B9: =COUNTIF(Cleaned_Data!H2:H156,A9) -> 3

Sheet Summary_WorkMode_Experience
A1: Work Mode & Experience Level Distribution
A3: Work Mode | B3: Count
A4: Remote | B4: =COUNTIF(Cleaned_Data!M2:M156,A4) -> 11
A5: Onsite | B5: =COUNTIF(Cleaned_Data!M2:M156,A5) -> 7
A6: Hybrid | B6: =COUNTIF(Cleaned_Data!M2:M156,A6) -> 4
A7: Not disclosed | B7: =COUNTIF(Cleaned_Data!M2:M156,A7) -> 133
A9: Experience Level | B9: Count
A10: Entry/Fresh | B10: =COUNTIF(Cleaned_Data!O2:O156,A10) -> 13
A11: Mid | B11: =COUNTIF(Cleaned_Data!O2:O156,A11) -> 17
A12: Senior | B12: =COUNTIF(Cleaned_Data!O2:O156,A12) -> 26
A13: Not disclosed | B13: =COUNTIF(Cleaned_Data!O2:O156,A13) -> 99

Sheet Salary_Transparency
A1: Salary Disclosure Analysis
A3: Metric | B3: Value
A4: Total Listings | B4: =COUNTA(Cleaned_Data!A2:A156) -> 155
A5: Salary Disclosed (any form) | B5: =COUNTIF(Cleaned_Data!P2:P156,"Yes") -> 4
A6: Salary Not Disclosed | B6: =COUNTIF(Cleaned_Data!P2:P156,"No") -> 151
A7: % Disclosed | B7: =B5/B4 -> 0.025806452
A8: PKR listings with usable monthly figure | B8: =COUNTIF(Cleaned_Data!R2:R156,"PKR") -> 2
A9: USD listings with usable monthly figure | B9: =COUNTIF(Cleaned_Data!R2:R156,"USD") -> 1
A10: Average Disclosed Monthly Salary - PKR only | B10: =AVERAGEIF(Cleaned_Data!R2:R156,"PKR",Cleaned_Data!S2:S156) -> 76250
A11: Min Disclosed Monthly Salary - PKR only | B11: {=MIN(IF(Cleaned_Data!R2:R156="PKR",Cleaned_Data!S2:S156))} -> 32500
A12: Max Disclosed Monthly Salary - PKR only | B12: {=MAX(IF(Cleaned_Data!R2:R156="PKR",Cleaned_Data!S2:S156))} -> 120000
A14: Note: 'Not disclosed' values were NEVER estimated or filled with assumed numbers — this reflects real market opacity, consistent with PBS informal-wage-reporting patterns. USD hourly-rate listing excluded from monthly PKR comparison (different unit).

Sheet Skills_Demand
A1: In-Demand Skills / Keywords (from job titles & notes)
A3: Skill/Keyword | B3: Mentions
A4: Sql | B4: =SUMPRODUCT(--ISNUMBER(SEARCH(" sql ", " "&Cleaned_Data!U2:U156&" "))) -> 7
A5: Power Bi | B5: =SUMPRODUCT(--ISNUMBER(SEARCH(" power bi ", " "&Cleaned_Data!U2:U156&" "))) -> 13
A6: Python | B6: =SUMPRODUCT(--ISNUMBER(SEARCH(" python ", " "&Cleaned_Data!U2:U156&" "))) -> 5
A7: Business Intelligence | B7: =SUMPRODUCT(--ISNUMBER(SEARCH(" business intelligence ", " "&Cleaned_Data!U2:U156&" "))) -> 9
A8: Analytics | B8: =SUMPRODUCT(--ISNUMBER(SEARCH(" analytics ", " "&Cleaned_Data!U2:U156&" "))) -> 9
A9: Reporting | B9: =SUMPRODUCT(--ISNUMBER(SEARCH(" reporting ", " "&Cleaned_Data!U2:U156&" "))) -> 4
A10: Etl | B10: =SUMPRODUCT(--ISNUMBER(SEARCH(" etl ", " "&Cleaned_Data!U2:U156&" "))) -> 0
A11: Excel | B11: =SUMPRODUCT(--ISNUMBER(SEARCH(" excel ", " "&Cleaned_Data!U2:U156&" "))) -> 1
A12: Machine Learning | B12: =SUMPRODUCT(--ISNUMBER(SEARCH(" machine learning ", " "&Cleaned_Data!U2:U156&" "))) -> 1
A13: Data Warehouse | B13: =SUMPRODUCT(--ISNUMBER(SEARCH(" data warehouse ", " "&Cleaned_Data!U2:U156&" "))) -> 2
A14: Statistics | B14: =SUMPRODUCT(--ISNUMBER(SEARCH(" statistics ", " "&Cleaned_Data!U2:U156&" "))) -> 0
A15: Erp | B15: =SUMPRODUCT(--ISNUMBER(SEARCH(" erp ", " "&Cleaned_Data!U2:U156&" "))) -> 1
